Tue 17 Dec 2024 09:58:47 PM IST - Cron is running
/usr/bin/python3: can't open file '/home/manaslaud/./task_exec.py': [Errno 2] No such file or directory
Fetched schedule for User ID 11: Date = Wednesday, December 17, Time = 10:19pm
Executing task for User ID: 11
Task scheduled for: Wednesday, December 17 10:19pm
Task executed at: 2024-12-17 22:04:01.756393
--------------------------------------------------------------------------------------------------------
